[32m2022-06-23 13:35:11 -0500[0m - dagster - [34mDEBUG[0m - get_data - 46e2d687-4182-4054-b8b4-157330d2dd59 - 15873 - auction_data - LOGS_CAPTURED - Started capturing logs for step: auction_data.
[32m2022-06-23 13:35:11 -0500[0m - dagster - [34mDEBUG[0m - get_data - 46e2d687-4182-4054-b8b4-157330d2dd59 - 15873 - auction_data - STEP_START - Started execution of step "auction_data".
[32m2022-06-23 13:35:16 -0500[0m - dagster - [34mERROR[0m - [31mget_data - 46e2d687-4182-4054-b8b4-157330d2dd59 - 15873 - auction_data - STEP_FAILURE - Execution of step "auction_data" failed.

dagster.core.errors.DagsterExecutionStepExecutionError: Error occurred while executing op "auction_data"::

TypeError: expected str, bytes or os.PathLike object, not TextIOWrapper

Stack Trace:
  File "/home/hg2355/.pyenv/versions/3.9.10/lib/python3.9/site-packages/dagster/core/execution/plan/utils.py", line 47, in solid_execution_error_boundary
    yield
  File "/home/hg2355/.pyenv/versions/3.9.10/lib/python3.9/site-packages/dagster/utils/__init__.py", line 406, in iterate_with_context
    next_output = next(iterator)
  File "/home/hg2355/.pyenv/versions/3.9.10/lib/python3.9/site-packages/dagster/core/execution/plan/compute_generator.py", line 66, in _coerce_solid_compute_fn_to_iterator
    result = fn(context, **kwargs) if context_arg_provided else fn(**kwargs)
  File "app.py", line 27, in auction_data
    with open(input_file) as input:
[0m
