[32m2022-06-21 13:18:36 -0500[0m - dagster - [34mDEBUG[0m - get_data - 5f4f90d2-547d-4bb3-a3f6-0a3cd39033d7 - 24709 - auction_data - LOGS_CAPTURED - Started capturing logs for step: auction_data.
[32m2022-06-21 13:18:36 -0500[0m - dagster - [34mDEBUG[0m - get_data - 5f4f90d2-547d-4bb3-a3f6-0a3cd39033d7 - 24709 - auction_data - STEP_START - Started execution of step "auction_data".
[32m2022-06-21 13:18:38 -0500[0m - dagster - [34mERROR[0m - [31mget_data - 5f4f90d2-547d-4bb3-a3f6-0a3cd39033d7 - 24709 - auction_data - STEP_FAILURE - Execution of step "auction_data" failed.

dagster.core.errors.DagsterExecutionStepExecutionError: Error occurred while executing op "auction_data"::

AttributeError: 'list' object has no attribute 'json'

Stack Trace:
  File "/home/hg2355/.pyenv/versions/3.9.10/lib/python3.9/site-packages/dagster/core/execution/plan/utils.py", line 47, in solid_execution_error_boundary
    yield
  File "/home/hg2355/.pyenv/versions/3.9.10/lib/python3.9/site-packages/dagster/utils/__init__.py", line 406, in iterate_with_context
    next_output = next(iterator)
  File "/home/hg2355/.pyenv/versions/3.9.10/lib/python3.9/site-packages/dagster/core/execution/plan/compute_generator.py", line 66, in _coerce_solid_compute_fn_to_iterator
    result = fn(context, **kwargs) if context_arg_provided else fn(**kwargs)
  File "app.py", line 18, in auction_data
    blob.upload_from_file(data.json)
[0m
